Workbook

Sheet Лист1
A1: Кол-во дней | B1: Р5 | E1: Кол-во дней | F1: Д5 | J1: Кол-во дней | K1: Ю5 | O1: Кол-во дней | P1: Д1 | T1: Кол-во дней | U1: ВО с выплатой дохода | Y1: Кол-во дней | Z1: А+ | AC1: Кол-во дней | AD1: 120/80 | AG1: Кол-во дней | AH1: Р1 | AK1: Кол-во дней | AL1: М3
B2: Дата | C2: Цена пая | F2: Дата | G2: Цена пая Руб | H2: Цена пая USD | K2: Дата | L2: Цена пая CNY | M2: Цена пая RUB | P2: Дата | Q2: Цена пая Руб | R2: Цена пая USD | U2: Дата | V2: Цена пая Руб | W2: Цена пая USD | Z2: Дата | AA2: Цена пая | AD2: Дата | AE2: Цена пая | AH2: Дата | AI2: Цена пая | AL2: Дата | AM2: Цена пая, RUB | AN2: Цена пая, GLD
B3: 44561 | C3: 798.77836 | F3: =$B3 -> 44561 | G3: =H3*VLOOKUP(F3,Лист2!$A:$M,13,0) -> 640.46046 | H3: 8.620784 | K3: =$B3 -> 44561 | L3: 85.372708 | M3: =VLOOKUP(K3,Лист2!$A:$N,14,0)*L3 -> 1000.3547 | P3: =$B3 -> 44561 | Q3: =VLOOKUP($P3,Лист2!$A:$M,13,0)*R3 -> 833.5371 | R3: 11.219652 | U3: =$B3 -> 44561 | V3: =VLOOKUP(U3,Лист2!$A:$M,13,0)*W3 -> 835.22364 | W3: 11.242353 | Z3: =$B3 -> 44561 | AA3: 692.7402 | AD3: =$B3 -> 44561 | AE3: 779.4344 | AH3: =$B3 -> 44561 | AI3: 920.36641 | AL3: =$B3 -> 44561 | AM3: 139.98972 | AN3: 0.032129841
B4: 44592 | C4: 789.93781 | F4: =$B4 -> 44592 | G4: =H4*VLOOKUP(F4,Лист2!$A:$M,13,0) -> 660.0882 | H4: 8.482527 | K4: =$B4 -> 44592 | L4: 85.372708 | M4: =VLOOKUP(K4,Лист2!$A:$N,14,0)*L4 -> 1044.7485 | P4: =$B4 -> 44592 | Q4: =VLOOKUP($P4,Лист2!$A:$M,13,0)*R4 -> 806.1146 | R4: 10.359053 | U4: =$B4 -> 44592 | V4: =VLOOKUP(U4,Лист2!$A:$M,13,0)*W4 -> 807.74566 | W4: 10.380014 | Z4: =$B4 -> 44592 | AA4: 649.1675 | AD4: =$B4 -> 44592 | AE4: 730.4088 | AH4: =$B4 -> 44592 | AI4: 881.21284 | AL4: =$B4 -> 44592 | AM4: 147.57606 | AN4: 0.032988947
B5: 44620 | C5: 820.4855 | F5: =$B5 -> 44620 | G5: =H5*VLOOKUP(F5,Лист2!$A:$M,13,0) -> 720.67875 | H5: 8.625873 | K5: =$B5 -> 44620 | L5: 85.372708 | M5: =VLOOKUP(K5,Лист2!$A:$N,14,0)*L5 -> 1161.675 | P5: =$B5 -> 44620 | Q5: =VLOOKUP($P5,Лист2!$A:$M,13,0)*R5 -> 865.48338 | R5: 10.359053 | U5: =$B5 -> 44620 | V5: =VLOOKUP(U5,Лист2!$A:$M,13,0)*W5 -> 867.23456 | W5: 10.380014 | Z5: =$B5 -> 44620 | AA5: 454.2745 | AD5: =$B5 -> 44620 | AE5: 511.1255 | AH5: =$B5 -> 44620 | AI5: 747.53827 | AL5: =$B5 -> 44620 | AM5: 189.96722 | AN5: 0.037428278
B6: 44651 | C6: 932.23732 | F6: =$B6 -> 44651 | G6: =H6*VLOOKUP(F6,Лист2!$A:$M,13,0) -> 785.63173 | H6: 9.343293 | K6: =$B6 -> 44651 | L6: 85.372708 | M6: =VLOOKUP(K6,Лист2!$A:$N,14,0)*L6 -> 1149.9704 | P6: =$B6 -> 44651 | Q6: =VLOOKUP($P6,Лист2!$A:$M,13,0)*R6 -> 871.04204 | R6: 10.359053 | U6: =$B6 -> 44651 | V6: =VLOOKUP(U6,Лист2!$A:$M,13,0)*W6 -> 872.80448 | W6: 10.380014 | Z6: =$B6 -> 44651 | AA6: 497.1248 | AD6: =$B6 -> 44651 | AE6: 559.3384 | AH6: =$B6 -> 44651 | AI6: 810.41182 | AL6: =$B6 -> 44651 | AM6: 186.57726 | AN6: 0.037092821
B7: 44681 | C7: 1009.7207 | F7: =$B7 -> 44681 | G7: =H7*VLOOKUP(F7,Лист2!$A:$M,13,0) -> 789.20967 | H7: 11.11192 | K7: =$B7 -> 44681 | L7: 85.372708 | M7: =VLOOKUP(K7,Лист2!$A:$N,14,0)*L7 -> 927.14761 | P7: =$B7 -> 44681 | Q7: =VLOOKUP($P7,Лист2!$A:$M,13,0)*R7 -> 657.91983 | R7: 9.2633843 | U7: =$B7 -> 44681 | V7: =VLOOKUP(U7,Лист2!$A:$M,13,0)*W7 -> 659.25104 | W7: 9.2821275 | Z7: =$B7 -> 44681 | AA7: 449.6212 | AD7: =$B7 -> 44681 | AE7: 505.8899 | AH7: =$B7 -> 44681 | AI7: 878.63797 | AL7: =$B7 -> 44681 | AM7: 133.19836 | AN7: 0.03134079
A8: формирование | B8: 44686 | C8: 1000 | F8: =$B8 -> 44686 | G8: =H8*VLOOKUP(F8,Лист2!$A:$M,13,0) -> 768.57951 | H8: 11.07208 | K8: =$B8 -> 44686 | L8: 85.372708 | M8: =VLOOKUP(K8,Лист2!$A:$N,14,0)*L8 -> 873.80674 | P8: =$B8 -> 44686 | Q8: =VLOOKUP($P8,Лист2!$A:$M,13,0)*R8 -> 643.02709 | R8: 9.2633843 | U8: =$B8 -> 44686 | V8: =VLOOKUP(U8,Лист2!$A:$M,13,0)*W8 -> 644.32816 | W8: 9.2821275 | Z8: =$B8 -> 44686 | AA8: 443.249 | AD8: =$B8 -> 44686 | AE8: 498.7202 | AH8: =$B8 -> 44686 | AI8: 874.05003 | AL8: =$B8 -> 44686 | AM8: 120.95701 | AN8: 0.02986593
A9: 26 | B9: 44712 | C9: 1043.6512 | F9: =$B9 -> 44712 | G9: =H9*VLOOKUP(F9,Лист2!$A:$M,13,0) -> 751.1688 | H9: 11.90489 | K9: =$B9 -> 44712 | L9: 85.372708 | M9: =VLOOKUP(K9,Лист2!$A:$N,14,0)*L9 -> 808.85518 | P9: =$B9 -> 44712 | Q9: =VLOOKUP($P9,Лист2!$A:$M,13,0)*R9 -> 618.90626 | R9: 9.8087287 | U9: =$B9 -> 44712 | V9: =VLOOKUP(U9,Лист2!$A:$M,13,0)*W9 -> 620.15853 | W9: 9.8285753 | Z9: =$B9 -> 44712 | AA9: 434.21 | AD9: =$B9 -> 44712 | AE9: 488.55 | AH9: =$B9 -> 44712 | AI9: 903.96529 | AL9: =$B9 -> 44712 | AM9: 91.88213 | AN9: 0.026030112
A10: 30 | B10: 44742 | C10: 1072.9673 | F10: =$B10 -> 44742 | G10: =H10*VLOOKUP(F10,Лист2!$A:$M,13,0) -> 702.76972 | H10: 13.73724 | K10: =$B10 -> 44742 | L10: 85.372708 | M10: =VLOOKUP(K10,Лист2!$A:$N,14,0)*L10 -> 700.32086 | P10: =$B10 -> 44742 | Q10: =VLOOKUP($P10,Лист2!$A:$M,13,0)*R10 -> 555.05518 | R10: 10.849822 | U10: =$B10 -> 44742 | V10: =VLOOKUP(U10,Лист2!$A:$M,13,0)*W10 -> 556.17825 | W10: 10.871775 | Z10: =$B10 -> 44742 | AA10: 432.73 | AD10: =$B10 -> 44742 | AE10: 486.88275 | AH10: =$B10 -> 44742 | AI10: 948.45586 | AL10: =$B10 -> 44742 | AM10: 66.337764 | AN10: 0.022117749
A11: 31 | B11: 44773 | C11: 1085.1313 | F11: =$B11 -> 44773 | G11: =H11*VLOOKUP(F11,Лист2!$A:$M,13,0) -> 853.5353 | H11: 13.92161 | K11: =$B11 -> 44773 | L11: 85.372708 | M11: =VLOOKUP(K11,Лист2!$A:$N,14,0)*L11 -> 796.51883 | P11: =$B11 -> 44773 | Q11: =VLOOKUP($P11,Лист2!$A:$M,13,0)*R11 -> 690.86061 | R11: 11.2683 | U11: =$B11 -> 44773 | V11: =VLOOKUP(U11,Лист2!$A:$M,13,0)*W11 -> 692.25847 | W11: 11.2911 | Z11: =$B11 -> 44773 | AA11: 464.05 | AD11: =$B11 -> 44773 | AE11: 522.11648 | AH11: =$B11 -> 44773 | AI11: 964.77895 | AL11: =$B11 -> 44773 | AM11: 86.656799 | AN11: 0.025279113
A12: 31 | B12: 44804 | C12: 1093.5835 | F12: =$B12 -> 44804 | G12: =H12*VLOOKUP(F12,Лист2!$A:$M,13,0) -> 819.17701 | H12: 13.56979 | K12: =$B12 -> 44804 | L12: 85.372708 | M12: =VLOOKUP(K12,Лист2!$A:$N,14,0)*L12 -> 740.60824 | P12: =$B12 -> 44804 | Q12: =VLOOKUP($P12,Лист2!$A:$M,13,0)*R12 -> 666.99391 | R12: 11.048854 | U12: =$B12 -> 44804 | V12: =VLOOKUP(U12,Лист2!$A:$M,13,0)*W12 -> 668.34348 | W12: 11.07121 | Z12: =$B12 -> 44804 | AA12: 490.79 | AD12: =$B12 -> 44804 | AE12: 552.20005 | AH12: =$B12 -> 44804 | AI12: 962.42256 | AL12: =$B12 -> 44804 | AM12: 80.793608 | AN12: 0.024408945
A13: 30 | B13: 44834 | C13: 1104.7195 | F13: =$B13 -> 44834 | G13: =H13*VLOOKUP(F13,Лист2!$A:$M,13,0) -> 744.43361 | H13: 12.96629 | K13: =$B13 -> 44834 | L13: 85.372708 | M13: =VLOOKUP(K13,Лист2!$A:$N,14,0)*L13 -> 693.22639 | P13: =$B13 -> 44834 | Q13: =VLOOKUP($P13,Лист2!$A:$M,13,0)*R13 -> 586.00265 | R13: 10.206794 | U13: =$B13 -> 44834 | V13: =VLOOKUP(U13,Лист2!$A:$M,13,0)*W13 -> 587.18834 | W13: 10.227446 | Z13: =$B13 -> 44834 | AA13: 426.43 | AD13: =$B13 -> 44834 | AE13: 479.79576 | AH13: =$B13 -> 44834 | AI13: 903.55956 | AL13: =$B13 -> 44834 | AM13: 77.221466 | AN13: 0.023863246
A14: 31 | B14: 44865 | C14: 1102.2097 | F14: =$B14 -> 44865 | G14: =H14*VLOOKUP(F14,Лист2!$A:$M,13,0) -> 766.01835 | H14: 12.44864 | K14: =$B14 -> 44865 | L14: 85.372708 | M14: =VLOOKUP(K14,Лист2!$A:$N,14,0)*L14 -> 717.38686 | P14: =$B14 -> 44865 | Q14: =VLOOKUP($P14,Лист2!$A:$M,13,0)*R14 -> 611.46242 | R14: 9.9369363 | U14: =$B14 -> 44865 | V14: =VLOOKUP(U14,Лист2!$A:$M,13,0)*W14 -> 612.69963 | W14: 9.9570423 | Z14: =$B14 -> 44865 | AA14: 476.86 | AD14: =$B14 -> 44865 | AE14: 536.52595 | AH14: =$B14 -> 44865 | AI14: 941.24624 | AL14: =$B14 -> 44865 | AM14: 78.900926 | AN14: 0.024121347
A15: 30 | B15: 44895 | C15: 1111.4511 | F15: =$B15 -> 44895 | G15: =H15*VLOOKUP(F15,Лист2!$A:$M,13,0) -> 787.16826 | H15: 12.88872 | K15: =$B15 -> 44895 | L15: 85.372708 | M15: =VLOOKUP(K15,Лист2!$A:$N,14,0)*L15 -> 722.93609 | P15: =$B15 -> 44895 | Q15: =VLOOKUP($P15,Лист2!$A:$M,13,0)*R15 -> 640.07518 | R15: 10.480288 | U15: =$B15 -> 44895 | V15: =VLOOKUP(U15,Лист2!$A:$M,13,0)*W15 -> 641.37028 | W15: 10.501493 | Z15: =$B15 -> 44895 | AA15: 472.17 | AD15: =$B15 -> 44895 | AE15: 531.24938 | AH15: =$B15 -> 44895 | AI15: 949.90715 | AL15: =$B15 -> 44895 | AM15: 86.50519 | AN15: 0.02525699
A16: 31 | B16: 44926 | C16: 1118.3898 | F16: =$B16 -> 44926 | G16: =H16*VLOOKUP(F16,Лист2!$A:$M,13,0) -> 870.07488 | H16: 12.37 | K16: =$B16 -> 44926 | L16: 85.441287 | M16: =VLOOKUP(K16,Лист2!$A:$N,14,0)*L16 -> 846.89404 | P16: =$B16 -> 44926 | Q16: =VLOOKUP($P16,Лист2!$A:$M,13,0)*R16 -> 736.78957 | R16: 10.47506 | U16: =$B16 -> 44926 | V16: =VLOOKUP(U16,Лист2!$A:$M,13,0)*W16 -> 738.28036 | W16: 10.496255 | Z16: =$B16 -> 44926 | AA16: 461.66 | AD16: =$B16 -> 44926 | AE16: 519.42891 | AH16: =$B16 -> 44926 | AI16: 954.60433 | AL16: =$B16 -> 44926 | AM16: 120.53925 | AN16: 0.02981431
A17: 31 | B17: 44957 | C17: 1122.7816 | F17: =$B17 -> 44957 | G17: =H17*VLOOKUP(F17,Лист2!$A:$M,13,0) -> 861.60529 | H17: 12.380685 | K17: =$B17 -> 44957 | L17: 85.38128 | M17: =VLOOKUP(K17,Лист2!$A:$N,14,0)*L17 -> 888.39222 | P17: =$B17 -> 44957 | Q17: =VLOOKUP($P17,Лист2!$A:$M,13,0)*R17 -> 738.44567 | R17: 10.610964 | U17: =$B17 -> 44957 | V17: =VLOOKUP(U17,Лист2!$A:$M,13,0)*W17 -> 739.93981 | W17: 10.632434 | Z17: =$B17 -> 44957 | AA17: 490.6 | AD17: =$B17 -> 44957 | AE17: 551.98893 | AH17: =$B17 -> 44957 | AI17: 959.31711 | AL17: =$B17 -> 44957 | AM17: 134.67608 | AN17: 0.03151416
A18: 28 | B18: 44985 | C18: 1127.5157 | F18: =$B18 -> 44985 | G18: =H18*VLOOKUP(F18,Лист2!$A:$M,13,0) -> 927.2116 | H18: 12.29197 | K18: =$B18 -> 44985 | L18: 85.544156 | M18: =VLOOKUP(K18,Лист2!$A:$N,14,0)*L18 -> 916.17791 | P18: =$B18 -> 44985 | Q18: =VLOOKUP($P18,Лист2!$A:$M,13,0)*R18 -> 788.58074 | R18: 10.454152 | U18: =$B18 -> 44985 | V18: =VLOOKUP(U18,Лист2!$A:$M,13,0)*W18 -> 790.17633 | W18: 10.475305 | Z18: =$B18 -> 44985 | AA18: 491.28 | AD18: =$B18 -> 44985 | AE18: 552.75572 | AH18: =$B18 -> 44985 | AI18: 955.02567 | AL18: =$B18 -> 44985 | AM18: 141.08362 | AN18: 0.03225513
F19: =B20 -> 45016 | G19: =H19*VLOOKUP(F19,Лист2!$A:$M,13,0) -> 945.46706 | H19: 12.265047 | K19: =$F19 -> 45016 | L19: 85.226977 | M19: =VLOOKUP(K19,Лист2!$A:$N,14,0)*L19 -> 953.86032 | P19: =$B20 -> 45016 | Q19: =VLOOKUP($P19,Лист2!$A:$M,13,0)*R19 -> 781.69575 | R19: 10.140528 | U19: =$B20 -> 45016 | V19: =VLOOKUP(U19,Лист2!$A:$M,13,0)*W19 -> 783.27741 | W19: 10.161046 | Z19: =$B20 -> 45016 | AA19: 507.48 | AD19: =$B20 -> 45016 | AE19: 570.98181 | AH19: =$B20 -> 45016 | AI19: 963.45251 | AL19: =$B20 -> 45016 | AM19: 179.96101 | AN19: 0.036429207
A20: 31 | B20: 45016 | C20: 1141.4948 | E20: формирование | F20: 45035 | G20: 996.4012 | H20: 12.21038 | J20: формирование | K20: 45035 | L20: 84.35259 | M20: 1000 | P20: =$B21 -> 45046 | Q20: =VLOOKUP($P20,Лист2!$A:$M,13,0)*R20 -> 826.50666 | R20: 10.265977 | U20: =$B21 -> 45046 | V20: =VLOOKUP(U20,Лист2!$A:$M,13,0)*W20 -> 828.17898 | W20: 10.286749 | Z20: =$B21 -> 45046 | AA20: 529.99 | AD20: =$B21 -> 45046 | AE20: 596.30611 | AH20: =$B21 -> 45046 | AI20: 972.87808 | AL20: =$B21 -> 45046 | AM20: 196.11702 | AN20: 0.038029284
A21: 30 | B21: 45046 | C21: 1139.2941 | E21: 11 | F21: 45046 | G21: 992.20305 | H21: 12.32408 | J21: 11 | K21: 45046 | L21: 85.22932 | M21: =L21*Лист2!N33 -> 987.4669 | P21: =$B22 -> 45077 | Q21: =VLOOKUP($P21,Лист2!$A:$M,13,0)*R21 -> 848.78825 | R21: 10.519491 | U21: =$B22 -> 45077 | V21: =VLOOKUP(U21,Лист2!$A:$M,13,0)*W21 -> 850.50565 | W21: 10.540775 | Z21: =$B22 -> 45077 | AA21: 547.63 | AD21: =$B22 -> 45077 | AE21: 616.16145 | AH21: =$B22 -> 45077 | AI21: 980.83675 | AL21: =$B22 -> 45077 | AM21: 192.55931 | AN21: 0.037682765
A22: 31 | B22: 45077 | C22: 1148.0026 | E22: 31 | F22: 45077 | G22: 1004.4161 | H22: 12.44827 | J22: 31 | K22: 45077 | L22: 85.77077 | M22: =L22*Лист2!N34 -> 975.98559 | P22: =$B23 -> 45107 | Q22: =VLOOKUP($P22,Лист2!$A:$M,13,0)*R22 -> 922.54337 | R22: 10.599792 | U22: =$B23 -> 45107 | V22: =VLOOKUP(U22,Лист2!$A:$M,13,0)*W22 -> 924.41 | W22: 10.621239 | Z22: =$B23 -> 45107 | AA22: 581.51 | AD22: =$B23 -> 45107 | AE22: 654.27741 | AH22: =$B23 -> 45107 | AI22: 977.46602 | AL22: =$B23 -> 45107 | AM22: 217.4298 | AN22: 0.040042395
A23: 30 | B23: 45107 | C23: 1169.43 | E23: 30 | F23: 45107 | G23: 1122.7399 | H23: 12.9 | J23: 30 | K23: 45107 | L23: 86.35 | M23: =L23*Лист2!N35 -> 1064.8682 | P23: 45138 | Q23: =VLOOKUP($P23,Лист2!$A:$M,13,0)*R23 -> 954.61015 | R23: 10.492723 | U23: =$B24 -> 45138 | V23: =VLOOKUP(U23,Лист2!$A:$M,13,0)*W23 -> 956.54167 | W23: 10.513954 | Z23: =$B24 -> 45138 | AA23: 670.34 | AD23: =$B24 -> 45138 | AE23: 754.22561 | AH23: =$B24 -> 45138 | AI23: 972.37871 | AL23: =$B24 -> 45138 | AM23: 240.01164 | AN23: 0.042070402
A24: 31 | B24: 45138 | C24: 1204.61 | E24: 31 | F24: 45138 | G24: 1149.0559 | H24: 12.63 | J24: 31 | K24: 45138 | L24: 87.83 | M24: =L24*Лист2!N36 -> 1124.9266 | O24: формирование | P24: 45146 | Q24: 994.63804 | R24: 10.3 | U24: =$B25 -> 45169 | V24: =VLOOKUP(U24,Лист2!$A:$M,13,0)*W24 -> 993.1482 | W24: 10.353026 | Z24: =$B25 -> 45169 | AA24: 729.23 | AD24: =$B25 -> 45169 | AE24: 820.48679 | AH24: =$B25 -> 45169 | AI24: 956.66422 | AL24: =$B25 -> 45169 | AM24: 263.79537 | AN24: 0.044105636
A25: 31 | B25: 45169 | C25: 1250.87 | E25: 31 | F25: 45169 | G25: 1260.4979 | H25: 13.14 | J25: 31 | K25: 45169 | L25: 91.21 | M25: =L25*Лист2!N43 -> 1150.2949 | O25: 23 | P25: 45169 | Q25: 1021.6364 | R25: 10.65 | U25: =$B26 -> 45199 | V25: =VLOOKUP(U25,Лист2!$A:$M,13,0)*W25 -> 1024.2137 | W25: 10.513954 | Z25: =$B26 -> 45199 | AA25: 694.42 | AD25: =$B26 -> 45199 | AE25: 781.31528 | AH25: =$B26 -> 45199 | AI25: 928.62159 | AL25: =$B26 -> 45199 | AM25: 250.49488 | AN25: 0.042979359
A26: 30 | B26: 45199 | C26: 1291.57 | E26: 30 | F26: 45199 | G26: 1356.0126 | H26: 13.92 | J26: 30 | K26: 45199 | L26: 93.41 | M26: =L26*Лист2!N44 -> 1167.7184 | O26: 30 | P26: 45199 | Q26: 1044.2856 | R26: 10.72 | U26: 45230 | V26: =VLOOKUP(U26,Лист2!$A:$M,13,0)*W26 -> 995.36335 | W26: 10.674882 | Z26: =$B27 -> 45230 | AA26: 703.15 | AD26: =$B27 -> 45230 | AE26: 791.13699 | AH26: =$B27 -> 45230 | AI26: 921.78649 | AL26: =$B27 -> 45230 | AM26: 249.69867 | AN26: 0.042910999
A27: 31 | B27: 45230 | C27: 1312.67 | E27: 31 | F27: 45230 | G27: 1334.3145 | H27: 14.31 | J27: 31 | K27: 45230 | L27: 94.43 | M27: =L27*Лист2!N45 -> 1188.1183 | O27: 31 | P27: 45230 | Q27: 1055.5164 | R27: 11.32 | T27: формирование | U27: 45231 | V27: 992.00363 | W27: 10.78 | Z27: =$B28 -> 45260 | AA27: 701.15 | AD27: =$B28 -> 45260 | AE27: 788.8823 | AH27: =$B28 -> 45260 | AI27: 963.92066 | AL27: =$B28 -> 45260 | AM27: 240.60183 | AN27: 0.042122096
A28: 30 | B28: 45260 | C28: 1304.22 | E28: 30 | F28: 45260 | G28: 1303.9297 | H28: 14.67 | J28: 30 | K28: 45260 | L28: 93.78 | M28: =L28*Лист2!N46 -> 1188.2864 | O28: 30 | P28: 45260 | Q28: 1050.6101 | R28: 11.82 | T28: 29 | U28: 45260 | V28: 983.94699 | W28: 11.07 | Z28: =$B29 -> 45291 | AA28: 713.99 | AD28: =$B29 -> 45291 | AE28: 803.33889 | AH28: =$B29 -> 45291 | AI28: 961.86077 | AL28: =$B29 -> 45291 | AM28: 257.80756 | AN28: 0.043602192
A29: 31 | B29: 45291 | C29: 1341.03 | E29: 31 | F29: 45291 | G29: 1348.0151 | H29: 15.03 | J29: 31 | K29: 45291 | L29: 95.26 | M29: =L29*Лист2!N47 -> 1213.5171 | O29: 31 | P29: 45291 | Q29: 1066.3939 | R29: 11.89 | T29: 31 | U29: 45291 | V29: 996.43701 | W29: 11.11 | Z29: =$B30 -> 45322 | AA29: 806.34 | AD29: =$B30 -> 45322 | AE29: 907.24577 | AH29: =$B30 -> 45322 | AI29: 970.42805 | AL29: =$B30 -> 45322 | AM29: 252.53883 | AN29: 0.043154351
A30: 31 | B30: 45322 | C30: 1352.1 | E30: 31 | F30: 45322 | G30: 1342.0092 | H30: 15.03 | J30: 31 | K30: 45322 | L30: 95.27 | M30: =L30*Лист2!N48 -> 1182.1102 | O30: 31 | P30: 45322 | Q30: 1082.179 | R30: 12.12 | T30: 31 | U30: 45322 | V30: 991.10457 | W30: 11.1 | Z30: =$B31 -> 45351 | AA30: 881.78 | AD30: =$B31 -> 45351 | AE30: 992.12344 | AH30: =$B31 -> 45351 | AI30: 959.50438 | AL30: =$B31 -> 45351 | AM30: 261.50598 | AN30: 0.043913831
A31: 29 | B31: 45351 | C31: 1375.72 | E31: 29 | F31: 45351 | G31: 1384.4688 | H31: 15.07 | J31: 29 | K31: 45351 | L31: 96.45 | M31: =L31*Лист2!N49 -> 1194.8226 | O31: 29 | P31: 45351 | Q31: 1109.7799 | R31: 12.08 | T31: 29 | U31: 45351 | V31: 1004.1304 | W31: 10.93 | Z31: =$B32 -> 45382 | AA31: 922.81 | AD31: =$B32 -> 45382 | AE31: 1038.2792 | AH31: =$B32 -> 45382 | AI31: 938.1564 | AL31: =$B32 -> 45382 | AM31: 329.73927 | AN31: 0.049311231
A32: 31 | B32: 45382 | C32: 1411.65 | E32: 31 | F32: 45382 | G32: 1439.0623 | H32: 15.58 | J32: 31 | K32: 45382 | L32: 98.29 | M32: =L32*Лист2!N50 -> 1153.384 | O32: 31 | P32: 45382 | Q32: 1141.6438 | R32: 12.36 | T32: 31 | U32: 45382 | V32: 1027.1099 | W32: 11.12 | Z32: 45412 | AA32: 976.79 | AD32: =$B33 -> 45412 | AE32: 1099.0239 | AH32: =$B33 -> 45412 | AI32: 933.7089 | AL32: =$B33 -> 45412 | AM32: 342.79542 | AN32: 0.050278002
A33: 30 | B33: 45412 | C33: 1443.99 | E33: 30 | F33: 45412 | G33: 1455.6165 | H33: 15.86 | J33: 30 | K33: 45412 | L33: 99.6 | M33: =L33*Лист2!N51 -> 1179.264 | O33: 30 | P33: 45412 | Q33: 1144.4854 | R33: 12.47 | T33: 30 | U33: 45412 | V33: 1019.6658 | W33: 11.11 | Y33: формирование | Z33: 45433 | AA33: 1000 | AD33: =$B34 -> 45443 | AE33: 1071.0038 | AH33: =$B34 -> 45443 | AI33: 890.71644 | AL33: =$B34 -> 45443 | AM33: 328.17304 | AN33: 0.049193979
A34: 31 | B34: 45443 | C34: 1509.91 | E34: 31 | F34: 45443 | G34: 1438.3861 | H34: 16.02 | J34: 31 | K34: 45443 | L34: 103.22 | M34: =L34*Лист2!N52 -> 1243.6978 | O34: 31 | P34: 45443 | Q34: 1107.9703 | R34: 12.34 | T34: 31 | U34: 45443 | V34: 975.9836 | W34: 10.87 | Y34: 10 | Z34: 45443 | AA34: 968.4 | AD34: =$B35 -> 45473 | AE34: 1078.4633 | AH34: =$B35 -> 45473 | AI34: 891.59033 | AL34: =$B35 -> 45473 | AM34: 313.86936 | AN34: 0.048109957
A35: 30 | B35: 45473 | C35: 1543.87 | E35: 30 | F35: 45473 | G35: 1368.5381 | H35: 15.96 | J35: 30 | K35: 45473 | L35: 104.28 | M35: =L35*Лист2!N53 -> 1322.479 | O35: 30 | P35: 45473 | Q35: 1032.4059 | R35: 12.04 | T35: 30 | U35: 45473 | V35: 927.79336 | W35: 10.82 | Y35: 30 | Z35: 45473 | AA35: 967.11 | AD35: =$B36 -> 45504 | AE35: 1042.6856 | AH35: =$B36 -> 45504 | AI35: 877.74847 | AL35: =$B36 -> 45504 | AM35: 336.98798 | AN35: 0.049850292
A36: 31 | B36: 45504 | C36: 1585.14 | E36: 31 | F36: 45504 | G36: 1330.88 | H36: 15.455742 | J36: 31 | K36: 45504 | L36: 106.15 | M36: =L36*Лист2!N54 -> 1405.426 | O36: 31 | P36: 45504 | Q36: 988.49 | R36: 11.479507 | T36: 31 | U36: 45504 | V36: 895.29 | W36: 10.397159 | Y36: 31 | Z36: 45504 | AA36: 975.79 | AD36: 45535 | AE36: 993.10729 | AH36: =$B37 -> 45535 | AI36: 878.60676 | AL36: =$B37 -> 45535 | AM36: 387.71877 | AN36: 0.053471075
A37: 31 | B37: 45535 | C37: 1615.36 | E37: 31 | F37: 45535 | G37: 1361.16 | H37: 14.927161 | J37: 31 | K37: 45535 | L37: 107.57 | M37: =L37*Лист2!N55 -> 1460.2627 | O37: 31 | P37: 45535 | Q37: 1009.28 | R37: 11.068269 | T37: 31 | U37: 45535 | V37: 894.42 | W37: 9.8086565 | Y37: 31 | Z37: 45535 | AA37: 970.26 | AC37: формирование | AD37: 45545 | AE37: 1000 | AH37: =$B38 -> 45565 | AI37: 872.97327 | AL37: =$B38 -> 45565 | AM37: 461.27951 | AN37: 0.058323367
A38: 30 | B38: 45565 | C38: 1667.55 | E38: 30 | F38: 45565 | G38: 1423.97 | H38: 15.275026 | J38: 30 | K38: 45565 | L38: 108.52 | M38: =L38*Лист2!N56 -> 1573.5943 | O38: 30 | P38: 45565 | Q38: 1044.12 | R38: 11.200348 | T38: 30 | U38: 45565 | V38: 907.48 | W38: 9.7346016 | Y38: 30 | Z38: 45565 | AA38: 1027.24 | AC38: 20 | AD38: 45565 | AE38: 1072.18 | AH38: =$B39 -> 45596 | AI38: 837.26846 | AL38: =$B39 -> 45596 | AM38: 536.56097 | AN38: 0.06290281
A39: 31 | B39: 45596 | C39: 1750 | E39: 31 | F39: 45596 | G39: 1488.28 | H39: 15.339519 | J39: 31 | K39: 45596 | L39: 112.93 | M39: =L39*Лист2!N57 -> 1547.7057 | O39: 31 | P39: 45596 | Q39: 1047.92 | R39: 10.800782 | T39: 31 | U39: 45596 | V39: 898.4 | W39: 9.2596983 | Y39: 31 | Z39: 45596 | AA39: 1021.44 | AC39: 31 | AD39: 45596 | AE39: 1025.71 | AH39: =$B40 -> 45626 | AI39: 864.00025 | AL39: =$B40 -> 45626 | AM39: 594.66679 | AN39: 0.066221246
A40: 30 | B40: 45626 | C40: 1700.46 | E40: 30 | F40: 45626 | G40: 1663.41 | H40: 15.438984 | J40: 30 | K40: 45626 | L40: 112.69 | M40: =L40*Лист2!N58 -> 1504.8623 | O40: 30 | P40: 45626 | Q40: 1188.67 | R40: 11.032672 | T40: 30 | U40: 45626 | V40: 1056.3 | W40: 9.8040763 | Y40: 30 | Z40: 45626 | AA40: 1038.02 | AC40: 30 | AD40: 45626 | AE40: 1055.3 | AH40: =$B41 -> 45657 | AI40: 941.60516 | AL40: =$B41 -> 45657 | AM40: 539.08003 | AN40: 0.063050296
...

Sheet Лист2
A1: № индекса | B1: 182495 | C1: 1601 | D1: 18085 | E1: 98888 | G1: 94292 | I1: 8833 | J1: 37639 | K1: 43763 | L1: 29903 | M1: 39 | N1: 8195
A2: Дата | B2: RUSFAR | C2: RGBITR | D2: MCFTR | E2: Cbonds индекс ЗО (в USD) | F2: Cbonds индекс ЗО (в RUB) | G2: RUCNYTR (в CNY) | H2: RUCNYTR (в RUB) | I2: GLDRUB | J2: CPI rub | K2: Cpi USD | L2: CPI cny | M2: USDRUB | N2: CNYRUB
A3: 44196 | J3: 4.91 | K3: 1.4 | L3: 0.2
A4: 44227 | J4: 5.19 | K4: 1.4 | L4: -0.3
A5: 44255 | J5: 5.67 | K5: 1.7 | L5: -0.2
A6: 44286 | J6: 5.79 | K6: 2.6 | L6: 0.4
A7: 44316 | J7: 5.53 | K7: 4.2 | L7: 0.9
A8: 44347 | J8: 6.02 | K8: 5 | L8: 1.3
A9: 44377 | J9: 6.5 | K9: 5.4 | L9: 1.1
A10: 44408 | J10: 6.5 | K10: 5.4 | L10: 1
A11: 44439 | J11: 6.68 | K11: 5.3 | L11: 0.8
A12: 44469 | J12: 7.4 | K12: 5.4 | L12: 0.7
A13: 44500 | J13: 8.13 | K13: 6.2 | L13: 1.5
A14: 44530 | J14: 8.4 | K14: 6.8 | L14: 2.3
A15: 44561 | B15: 1282.06 | C15: 589.78 | D15: 7250.04 | E15: 109.71428 | F15: 8150.959 | G15: 99.59 | H15: 1166.9458 | I15: 4357 | J15: 8.39 | K15: 7 | L15: 1.5 | M15: 74.2926 | N15: 11.7175
A16: 44592 | B16: 1291.79 | C16: 564.69 | D16: 6794.02 | E16: 101.29869 | F16: 7882.8011 | G16: 99.59 | H16: 1218.7326 | I16: 4473.5 | J16: 8.73 | K16: 7.5 | L16: 0.9 | M16: 77.8174 | N16: 12.2375
A17: 44620 | B17: 1300.82 | C17: 479.03 | D17: 4754.32 | E17: 101.29869 | F17: 8463.354 | G17: 99.59 | H17: 1355.1311 | I17: 5075.5 | J17: 9.15 | K17: 7.9 | L17: 0.9 | M17: 83.5485 | N17: 13.6071
A18: 44651 | B18: 1322.45 | C18: 519.32 | D18: 5202.78 | E18: 101.29869 | F18: 8517.7109 | G18: 99.59 | H18: 1341.4773 | I18: 5030.01 | J18: 16.69 | K18: 8.5 | L18: 1.5 | M18: 84.0851 | N18: 13.47
A19: 44681 | B19: 1340.79 | C19: 563.04 | D19: 4705.62 | E19: 90.58441 | F19: 6433.6399 | G19: 99.59 | H19: 1081.5474 | I19: 4250 | J19: 17.83 | K19: 8.3 | L19: 2.1 | M19: 71.0237 | N19: 10.86
A20: 44686 | B20: 1344.34 | C20: 560.1 | D20: 4638.93 | E20: 90.58441 | F20: 6288.0074 | G20: 99.59 | H20: 1019.3236 | I20: 4050 | M20: 69.416 | N20: 10.2352
A21: 44712 | B21: 1357.17 | C21: 579.27 | D21: 4544.33 | E21: 95.917202 | F21: 6052.1356 | G21: 99.59 | H21: 943.5555 | I21: 3529.84 | J21: 17.1 | K21: 8.6 | L21: 2.1 | M21: 63.0975 | N21: 9.4744
A22: 44742 | B22: 1368.19 | C22: 607.78 | D22: 4256.3 | E22: 106.0978 | F22: 5427.7512 | G22: 99.59 | H22: 816.94673 | I22: 2999.3 | J22: 15.9 | K22: 9.1 | L22: 2.5 | M22: 51.158 | N22: 8.2031
A23: 44773 | B23: 1378.08 | C23: 618.24 | D23: 4323.46 | E23: 110.19 | F23: 6755.76 | G23: 99.59 | H23: 929.16474 | I23: 3428 | J23: 15.1 | K23: 8.5 | L23: 2.7 | M23: 61.3101 | N23: 9.3299
A24: 44804 | B24: 1388.01 | C24: 616.73 | D24: 4687.26 | E24: 108.04409 | F24: 6522.3732 | G24: 99.59 | H24: 863.94325 | I24: 3310 | J24: 14.3 | K24: 8.3 | L24: 2.5 | M24: 60.3677 | N24: 8.675
A25: 44834 | B25: 1396.81 | C25: 579.01 | D25: 3832.96 | E25: 99.809783 | F25: 5730.3791 | G25: 99.59 | H25: 808.6708 | I25: 3236 | J25: 13.68 | K25: 8.2 | L25: 2.8 | M25: 57.413 | N25: 8.12
A26: 44865 | B26: 1405.85 | C26: 603.16 | D26: 4429.18 | E26: 97.170912 | F26: 5979.3441 | G26: 99.59 | H26: 808.6708 | I26: 3271 | J26: 12.63 | K26: 7.7 | L26: 2.1 | M26: 61.5343 | N26: 8.403
A27: 44895 | B27: 1414.34 | C27: 608.71 | D27: 4445.38 | E27: 102.48421 | F27: 6259.1414 | G27: 99.59 | H27: 843.32812 | I27: 3425 | J27: 11.98 | K27: 7.1 | L27: 1.6 | M27: 61.0742 | N27: 8.468
A28: 44926 | B28: 1422.55 | C28: 611.72 | D28: 4548.82 | E28: 102.4331 | F28: 7204.8882 | G28: 99.67 | H28: 987.92904 | I28: 4043 | J28: 11.94 | K28: 6.5 | L28: 1.8 | M28: 70.3375 | N28: 9.912
A29: 44957 | B29: 1431.6 | C29: 614.74 | D29: 4712.84 | E29: 104.5795 | F29: 7277.9698 | G29: 99.6 | H29: 1036.338 | I29: 4273.51 | J29: 11.77 | K29: 6.4 | L29: 2.1 | M29: 69.5927 | N29: 10.405
A30: 44985 | B30: 1439.4 | C30: 611.99 | D30: 4771.2 | E30: 100.6713 | F30: 7593.8677 | G30: 99.79 | H30: 1068.7509 | I30: 4373.99 | J30: 10.99 | K30: 6 | L30: 1 | M30: 75.4323 | N30: 10.71
A31: 45016 | B31: 1448.39 | C31: 617.39 | D31: 5189.44 | E31: 103.2963 | F31: 7962.7296 | G31: 99.42 | H31: 1112.7086 | I31: 4940.02 | J31: 3.51 | K31: 5 | L31: 0.7 | M31: 77.0863 | N31: 11.192
A32: 45035 | B32: 1453.81 | C32: 618.99 | D32: 5525.66 | E32: 98.7792 | F32: 8060.6593 | G32: 98.4 | H32: 1166.532 | I32: 5215.01 | M32: 81.6028 | N32: 11.855
A33: 45046 | B33: 1456.35 | C33: 623.43 | D33: 5585.84 | E33: 98.7858 | F33: 7953.1756 | G33: 98.27 | H33: 1138.5562 | I33: 5157 | J33: 2.31 | K33: 4.9 | L33: 0.1 | M33: 80.5093 | N33: 11.586
A34: 45077 | B34: 1465.81 | C34: 628.53 | D34: 5885.95 | E34: 99.787 | F34: 8051.5336 | G34: 99.14 | H34: 1128.1141 | I34: 5110.01 | J34: 2.51 | K34: 4.1 | L34: 0.2 | M34: 80.6872 | N34: 11.379
A35: 45107 | B35: 1474.54 | C35: 626.37 | D35: 6151.53 | E35: 100.0094 | F35: 8704.2281 | G35: 99.46 | H35: 1226.5407 | I35: 5429.99 | J35: 3.25 | K35: 3 | L35: 0 | M35: 87.0341 | N35: 12.332
A36: 45138 | B36: 1484.17 | C36: 623.11 | D36: 6805.15 | E36: 97.505 | F36: 8870.8391 | G36: 99.14 | H36: 1269.7851 | I36: 5705 | J36: 4.3 | K36: 3.2 | L36: -0.3 | M36: 90.9783 | N36: 12.808
A37: 45146 | B37: 1486.77 | C37: 620.71 | D37: 6831.3 | E37: 99.0759 | F37: 9567.4426 | G37: 98.98 | H37: 1328.2126 | I37: 5959.99 | M37: 96.5668 | N37: 13.419
A38: 45169 | B38: 1496.94 | C38: 613.04 | D38: 7147.21 | E38: 100.7902 | F38: 9668.6325 | G38: 99.57 | H38: 1311.3369 | I38: 5980.99 | J38: 5.15 | K38: 3.7 | L38: 0.1 | M38: 95.9283 | N38: 13.17
A39: 45199 | B39: 1511.4 | C39: 595.07 | D39: 6937.46 | E39: 105.1211 | F39: 10240.34 | G39: 99.56 | H39: 1343.3631 | I39: 5828.26 | J39: 6 | K39: 3.7 | L39: 0 | M39: 97.4147 | N39: 13.493
A40: 45230 | B40: 1528.56 | C40: 590.69 | D40: 7117.04 | E40: 108.6065 | F40: 10126.85 | G40: 99.74 | H40: 1265.2019 | I40: 5818.99 | J40: 6.69 | K40: 3.2 | L40: -0.2 | M40: 93.2435 | N40: 12.685
...
